Workbook

Sheet Guide
A1: K-pop idol sim: economy, growth and revenue model
A3: What each tab does
A4: Inputs: numbers every tab shares (Roblox cut, DevEx rate, gems per pull, pity, event length, regions where paid random items are restricted).
A5: Pacing: upgrade costs, zones and walls. How long free and paying players wait at each point, checked against targets.
A6: Gems: free gem income, Robux gem bundles, and what it costs to reach pity sooner.
A7: Odds: pull odds (the exact numbers the game must show), odds with a luck boost on, pity maths, and the average cost of each chase item.
A8: Revenue: the chance a new player buys each item, revenue per player, a monthly projection and a sensitivity grid.
A9: Growth: 26 weeks of new players (organic, friends, off-Roblox content, ads, comebacks), a retention heat map by install week, Creator Rewards, and whether ads pay back.
A10: Heat maps: revenue by product and player age, and planned play time by feature and player age.
A11: Tracking: the analytics events to log so these heat maps fill with real data after launch.
A13: Colours
A14: Blue text = an input you can change. Black text = calculated. Green text = pulled from another tab.
... A28: Rewarded video ads (Roblox only offers them to games with 100K+ average daily players), trading, and day-by-day timing inside a week.

Sheet Inputs
A1: Shared inputs
A2: Blue = change me. Yellow = check this, or replace it with real data.
A4: Input | B4: Value | C4: Unit | D4: Note / source
A5: DevEx rate (cash you get per Robux you exchange) | B5: 0.0038 | C5: USD per Robux | D5: Roblox Creator Docs, "Earn on Roblox": 10,000 Robux = $38.
A6: Your share of Robux from in-game sales | B6: 0.7 | C6: % | D6: Roblox Creator Docs: creators generally earn 70% of what they sell in Robux in their game.
A7: What a player pays per Robux | B7: 0.0125 | C7: USD per Robux | D7: About $9.99 for 800 Robux. Varies by package, platform and country.
A8: Gems per single pull | B8: 100 | C8: gems | D8: Design choice.
A9: Pity: Center or better guaranteed by pull # | B9: 60 | C9: pulls | D9: Design choice.
A10: Comeback (event) length | B10: 21 | C10: days | D10: Design choice.
A11: Minutes an engaged player plays per day | B11: 45 | C11: minutes | D11: Placeholder. Replace with average session length x sessions per day.
A12: Share of your players where paid random items are restricted | B12: 0.15 | C12: % | D12: Roblox names Australia, Belgium, Netherlands, UK and Brazil as regulated markets (DevForum, May 2026). Placeholder share: check players by country in Creator Analytics.
A13: Restricted players buy pack-related items at this share of the normal rate | B13: 0.3 | C13: % | D13: They cannot buy packs with Robux-bought gems, but may still buy boosts for earned packs. Placeholder.
A15: Calculated
A16: Of every $1 a player spends, you keep | B16: =B6*B5/B7 -> 0.2128 | C16: % | D16: After Roblox's 30% and the DevEx exchange rate.

Sheet Pacing
A1: Pacing: fast early, slower later
A2: Each upgrade costs more than the last and boosts Hype a little. Entering a zone means paying a wall, then Hype jumps. Simulated for active play only.
A4: Upgrade inputs
A5: Hype per click at start | B5: 1 | C5: Design choice.
A6: Clicks per second while playing | B6: 4 | C6: Average including pauses. Placeholder.
A7: First upgrade cost (Hype) | B7: 12 | C7: Design choice.
A8: Each upgrade boosts Hype by | B8: 0.1 | C8: Multiplies: 10 upgrades = 1.1^10 = 2.6x.
A9: Payer owns 2x Hype? (1 = yes, 0 = no) | B9: 1 | C9: Scenario switch for the payer columns.
A10: Payer owns Auto-Stream? (1 = yes, 0 = no) | B10: 1 | C10: Scenario switch for the payer columns.
A11: Auto-Stream speed vs. clicking by hand | B11: 1.25 | C11: Placeholder: auto-clicks a bit faster than a person keeps up.
A12: Payer Hype multiplier | B12: =IF(B9=1,2,1)*IF(B10=1,B11,1) -> 2.5 | C12: Applies to every payer column below.
A14: Zone | B14: Name | C14: Starts at upgrade # | D14: Cost growth per upgrade | E14: Hype boost on entry | F14: Wall (x that upgrade's cost) | G14: Total Hype multiplier | H14: Unlock cost (Hype) | I14: Free player arrives (min played) | J14: Free player arrives (day) | K14: Payer arrives (min played) | L14: Payer is faster by | M14: Wall wait, free player (min)
A15: 1 | B15: Practice Room | C15: 1 | D15: 1.18 | E15: 1 | F15: 0 | G15: =E15 -> 1 | H15: =IF(A15=1,0,INDEX($E$53:$E$172,C15)) -> 0 | I15: =IF(A15=1,0,INDEX($I$53:$I$172,C15)) -> 0 | J15: =IF(A15=1,1,MAX(1,ROUNDUP(I15/Inputs!$B$11,0))) -> 1 | K15: =IF(A15=1,0,INDEX($M$53:$M$172,C15)) -> 0 | L15: =IF(A15=1,"-",I15/K15) -> - | M15: =IF(A15=1,0,INDEX($H$53:$H$172,C15)/60) -> 0
A16: 2 | B16: Busking Street | C16: 30 | D16: 1.24 | E16: 2 | F16: 2 | G16: =G15*E16 -> 2 | H16: =IF(A16=1,0,INDEX($E$53:$E$172,C16)) -> 3064.2848 | I16: =IF(A16=1,0,INDEX($I$53:$I$172,C16)) -> 5.7856009 | J16: =IF(A16=1,1,MAX(1,ROUNDUP(I16/Inputs!$B$11,0))) -> 1 | K16: =IF(A16=1,0,INDEX($M$53:$M$172,C16)) -> 2.3142404 | L16: =IF(A16=1,"-",I16/K16) -> 2.5 | M16: =IF(A16=1,0,INDEX($H$53:$H$172,C16)/60) -> 1.2073169
A17: 3 | B17: Showcase Hall | C17: 44 | D17: 1.3 | E17: 1.6 | F17: 6 | G17: =G16*E17 -> 3.2 | H17: =IF(A17=1,0,INDEX($E$53:$E$172,C17)) -> 195828.39 | I17: =IF(A17=1,0,INDEX($I$53:$I$172,C17)) -> 20.364042 | J17: =IF(A17=1,1,MAX(1,ROUNDUP(I17/Inputs!$B$11,0))) -> 1 | K17: =IF(A17=1,0,INDEX($M$53:$M$172,C17)) -> 8.1456167 | L17: =IF(A17=1,"-",I17/K17) -> 2.5 | M17: =IF(A17=1,0,INDEX($H$53:$H$172,C17)/60) -> 7.9012488
A18: 4 | B18: Music Show Stage | C18: 52 | D18: 1.28 | E18: 1.6 | F18: 2 | G18: =G17*E18 -> 5.12 | H18: =IF(A18=1,0,INDEX($E$53:$E$172,C18)) -> 524285.48 | I18: =IF(A18=1,0,INDEX($I$53:$I$172,C18)) -> 38.473872 | J18: =IF(A18=1,1,MAX(1,ROUNDUP(I18/Inputs!$B$11,0))) -> 1 | K18: =IF(A18=1,0,INDEX($M$53:$M$172,C18)) -> 15.389549 | L18: =IF(A18=1,"-",I18/K18) -> 2.5 | M18: =IF(A18=1,0,INDEX($H$53:$H$172,C18)/60) -> 7.9299586
A19: 5 | B19: Fan Meeting Hall | C19: 62 | D19: 1.2 | E19: 1.6 | F19: 1.5 | G19: =G18*E19 -> 8.192 | H19: =IF(A19=1,0,INDEX($E$53:$E$172,C19)) -> 4352112 | I19: =IF(A19=1,0,INDEX($I$53:$I$172,C19)) -> 90.304099 | J19: =IF(A19=1,1,MAX(1,ROUNDUP(I19/Inputs!$B$11,0))) -> 3 | K19: =IF(A19=1,0,INDEX($M$53:$M$172,C19)) -> 36.12164 | L19: =IF(A19=1,"-",I19/K19) -> 2.5 | M19: =IF(A19=1,0,INDEX($H$53:$H$172,C19)/60) -> 17.624379
A20: 6 | B20: Concert Hall | C20: 74 | D20: 1.2 | E20: 1.6 | F20: 1.5 | G20: =G19*E20 -> 13.1072 | H20: =IF(A20=1,0,INDEX($E$53:$E$172,C20)) -> 38803868 | I20: =IF(A20=1,0,INDEX($I$53:$I$172,C20)) -> 206.41681 | J20: =IF(A20=1,1,MAX(1,ROUNDUP(I20/Inputs!$B$11,0))) -> 5 | K20: =IF(A20=1,0,INDEX($M$53:$M$172,C20)) -> 82.566723 | L20: =IF(A20=1,"-",I20/K20) -> 2.5 | M20: =IF(A20=1,0,INDEX($H$53:$H$172,C20)/60) -> 31.293675
A21: 7 | B21: Arena | C21: 86 | D21: 1.2 | E21: 1.6 | F21: 1.5 | G21: =G20*E21 -> 20.97152 | H21: =IF(A21=1,0,INDEX($E$53:$E$172,C21)) -> 3.4597918e+08 | I21: =IF(A21=1,0,INDEX($I$53:$I$172,C21)) -> 412.5854 | J21: =IF(A21=1,1,MAX(1,ROUNDUP(I21/Inputs!$B$11,0))) -> 10 | K21: =IF(A21=1,0,INDEX($M$53:$M$172,C21)) -> 165.03416 | L21: =IF(A21=1,"-",I21/K21) -> 2.5 | M21: =IF(A21=1,0,INDEX($H$53:$H$172,C21)/60) -> 55.564743
A22: 8 | B22: Stadium | C22: 98 | D22: 1.2 | E22: 1.6 | F22: 1.5 | G22: =G21*E22 -> 33.554432 | H22: =IF(A22=1,0,INDEX($E$53:$E$172,C22)) -> 3.0847851e+09 | I22: =IF(A22=1,0,INDEX($I$53:$I$172,C22)) -> 778.65633 | J22: =IF(A22=1,1,MAX(1,ROUNDUP(I22/Inputs!$B$11,0))) -> 18 | K22: =IF(A22=1,0,INDEX($M$53:$M$172,C22)) -> 311.46253 | L22: =IF(A22=1,"-",I22/K22) -> 2.5 | M22: =IF(A22=1,0,INDEX($H$53:$H$172,C22)/60) -> 98.660215
A23: 9 | B23: World Tour | C23: 110 | D23: 1.2 | E23: 1.6 | F23: 1.5 | G23: =G22*E23 -> 53.687091 | H23: =IF(A23=1,0,INDEX($E$53:$E$172,C23)) -> 2.7504254e+10 | I23: =IF(A23=1,0,INDEX($I$53:$I$172,C23)) -> 1428.6483 | J23: =IF(A23=1,1,MAX(1,ROUNDUP(I23/Inputs!$B$11,0))) -> 32 | K23: =IF(A23=1,0,INDEX($M$53:$M$172,C23)) -> 571.45932 | L23: =IF(A23=1,"-",I23/K23) -> 2.5 | M23: =IF(A23=1,0,INDEX($H$53:$H$172,C23)/60) -> 175.18012
A24: Zone 1 has no wall. A wall is a one-time unlock cost; the first big one (Showcase Hall) is where the Debut Pack offer appears.
A25: Does the curve hit the targets?
A26: Phase | B26: From (min played) | C26: To (min played) | D26: Target wait, fastest (sec) | E26: Target wait, slowest (sec) | F26: Actual average wait (sec) | G26: Status
A27: First minute | B27: 0 | C27: 1 | D27: 2 | E27: 8 | F27: =IFERROR(AVERAGEIFS($H$53:$H$172,$I$53:$I$172,">="&B27,$I$53:$I$172,"<"&C27,$C$53:$C$172,0),"none") -> 4.5445524 | G27: =IF(ISNUMBER(F27),IF(F27<D27,"Too fast",IF(F27>E27,"Too slow","OK")),"No upgrades here") -> OK
A28: Minutes 1-5 | B28: 1 | C28: 5 | D28: 8 | E28: 30 | F28: =IFERROR(AVERAGEIFS($H$53:$H$172,$I$53:$I$172,">="&B28,$I$53:$I$172,"<"&C28,$C$53:$C$172,0),"none") -> 12.95073 | G28: =IF(ISNUMBER(F28),IF(F28<D28,"Too fast",IF(F28>E28,"Too slow","OK")),"No upgrades here") -> OK
A29: Minutes 5-15 | B29: 5 | C29: 15 | D29: 25 | E29: 90 | F29: =IFERROR(AVERAGEIFS($H$53:$H$172,$I$53:$I$172,">="&B29,$I$53:$I$172,"<"&C29,$C$53:$C$172,0),"none") -> 30.81781 | G29: =IF(ISNUMBER(F29),IF(F29<D29,"Too fast",IF(F29>E29,"Too slow","OK")),"No upgrades here") -> OK
A30: Minutes 15-30 | B30: 15 | C30: 30 | D30: 60 | E30: 180 | F30: =IFERROR(AVERAGEIFS($H$53:$H$172,$I$53:$I$172,">="&B30,$I$53:$I$172,"<"&C30,$C$53:$C$172,0),"none") -> 79.082689 | G30: =IF(ISNUMBER(F30),IF(F30<D30,"Too fast",IF(F30>E30,"Too slow","OK")),"No upgrades here") -> OK
A31: Minutes 30-60 | B31: 30 | C31: 60 | D31: 120 | E31: 300 | F31: =IFERROR(AVERAGEIFS($H$53:$H$172,$I$53:$I$172,">="&B31,$I$53:$I$172,"<"&C31,$C$53:$C$172,0),"none") -> 168.76382 | G31: =IF(ISNUMBER(F31),IF(F31<D31,"Too fast",IF(F31>E31,"Too slow","OK")),"No upgrades here") -> OK
A32: Hour 1 to day 7 | B32: 60 | C32: =7*Inputs!$B$11 -> 315 | D32: 240 | E32: 600 | F32: =IFERROR(AVERAGEIFS($H$53:$H$172,$I$53:$I$172,">="&B32,$I$53:$I$172,"<"&C32,$C$53:$C$172,0),"none") -> 534.65987 | G32: =IF(ISNUMBER(F32),IF(F32<D32,"Too fast",IF(F32>E32,"Too slow","OK")),"No upgrades here") -> OK
A33: Weeks 2-3 | B33: =C32 -> 315 | C33: =21*Inputs!$B$11 -> 945 | D33: 600 | E33: 1800 | F33: =IFERROR(AVERAGEIFS($H$53:$H$172,$I$53:$I$172,">="&B33,$I$53:$I$172,"<"&C33,$C$53:$C$172,0),"none") -> 1531.2774 | G33: =IF(ISNUMBER(F33),IF(F33<D33,"Too fast",IF(F33>E33,"Too slow","OK")),"No upgrades here") -> OK
A34: Walls are left out of these averages; their waits are in the zone table above.
A36: Where a player is after X minutes of play
A37: Minutes played | B37: Roughly day | C37: Upgrades bought (free) | D37: Zone (free) | E37: Wait for next upgrade (sec, free) | F37: Upgrades bought (payer) | G37: Zone (payer)
A38: 1 | B38: =MAX(1,ROUNDUP(A38/Inputs!$B$11,0)) -> 1 | C38: =IFERROR(MATCH(A38,$I$53:$I$172,1),0) -> 12 | D38: =INDEX($B$15:$B$23,IF(C38=0,1,INDEX($B$53:$B$172,C38))) -> Practice Room | E38: =IF(C38>=ROWS($H$53:$H$172),"-",INDEX($H$53:$H$172,C38+1)) -> 6.9661548 | F38: =IFERROR(MATCH(A38,$M$53:$M$172,1),0) -> 21 | G38: =INDEX($B$15:$B$23,IF(F38=0,1,INDEX($B$53:$B$172,F38))) -> Practice Room
A39: 5 | B39: =MAX(1,ROUNDUP(A39/Inputs!$B$11,0)) -> 1 | C39: =IFERROR(MATCH(A39,$I$53:$I$172,1),0) -> 29 | D39: =INDEX($B$15:$B$23,IF(C39=0,1,INDEX($B$53:$B$172,C39))) -> Practice Room | E39: =IF(C39>=ROWS($H$53:$H$172),"-",INDEX($H$53:$H$172,C39+1)) -> 72.439014 | F39: =IFERROR(MATCH(A39,$M$53:$M$172,1),0) -> 43 | G39: =INDEX($B$15:$B$23,IF(F39=0,1,INDEX($B$53:$B$172,F39))) -> Busking Street
A40: 10 | B40: =MAX(1,ROUNDUP(A40/Inputs!$B$11,0)) -> 1 | C40: =IFERROR(MATCH(A40,$I$53:$I$172,1),0) -> 40 | D40: =INDEX($B$15:$B$23,IF(C40=0,1,INDEX($B$53:$B$172,C40))) -> Busking Street | E40: =IF(C40>=ROWS($H$53:$H$172),"-",INDEX($H$53:$H$172,C40+1)) -> 45.096234 | F40: =IFERROR(MATCH(A40,$M$53:$M$172,1),0) -> 48 | G40: =INDEX($B$15:$B$23,IF(F40=0,1,INDEX($B$53:$B$172,F40))) -> Showcase Hall
A41: 15 | B41: =MAX(1,ROUNDUP(A41/Inputs!$B$11,0)) -> 1 | C41: =IFERROR(MATCH(A41,$I$53:$I$172,1),0) -> 43 | D41: =INDEX($B$15:$B$23,IF(C41=0,1,INDEX($B$53:$B$172,C41))) -> Busking Street | E41: =IF(C41>=ROWS($H$53:$H$172),"-",INDEX($H$53:$H$172,C41+1)) -> 474.07493 | F41: =IFERROR(MATCH(A41,$M$53:$M$172,1),0) -> 51 | G41: =INDEX($B$15:$B$23,IF(F41=0,1,INDEX($B$53:$B$172,F41))) -> Showcase Hall
A42: 30 | B42: =MAX(1,ROUNDUP(A42/Inputs!$B$11,0)) -> 1 | C42: =IFERROR(MATCH(A42,$I$53:$I$172,1),0) -> 50 | D42: =INDEX($B$15:$B$23,IF(C42=0,1,INDEX($B$53:$B$172,C42))) -> Showcase Hall | E42: =IF(C42>=ROWS($H$53:$H$172),"-",INDEX($H$53:$H$172,C42+1)) -> 136.29616 | F42: =IFERROR(MATCH(A42,$M$53:$M$172,1),0) -> 61 | G42: =INDEX($B$15:$B$23,IF(F42=0,1,INDEX($B$53:$B$172,F42))) -> Music Show Stage
A43: 45 | B43: =MAX(1,ROUNDUP(A43/Inputs!$B$11,0)) -> 1 | C43: =IFERROR(MATCH(A43,$I$53:$I$172,1),0) -> 54 | D43: =INDEX($B$15:$B$23,IF(C43=0,1,INDEX($B$53:$B$172,C43))) -> Music Show Stage | E43: =IF(C43>=ROWS($H$53:$H$172),"-",INDEX($H$53:$H$172,C43+1)) -> 156.18265 | F43: =IFERROR(MATCH(A43,$M$53:$M$172,1),0) -> 66 | G43: =INDEX($B$15:$B$23,IF(F43=0,1,INDEX($B$53:$B$172,F43))) -> Fan Meeting Hall
...

Sheet Gems
A1: Gems: free income, bundles and pity
A2: Gems are the one premium currency: bought with Robux, or earned slowly by playing. Packs bought with gems count as paid random items.
A4: Free gems an engaged free player earns per day
A5: Attendance calendar (average per day) | B5: 50
A6: Three daily quests | B6: 75
A7: Weekly quests (per-day share) | B7: 40
A8: Achievements and small events (per-day average) | B8: 25
A9: Stage and boss drops | B9: 150
A10: Daily cap on stage and boss gems | B10: 120 | C10: The cap keeps bought gems valuable without limiting play time.
A11: Free gems per day | B11: =SUM(B5:B8)+MIN(B9,B10) -> 310
A12: Gems per pull | B12: =Inputs!$B$8 -> 100
A13: Free pulls per day | B13: =B11/B12 -> 3.1
A14: Pity at pull # | B14: =Inputs!$B$9 -> 60
A15: Days for a free player to reach pity | B15: =B14*B12/B11 -> 19.354839
A16: Comeback length (days) | B16: =Inputs!$B$10 -> 21
A17: Free pulls over one comeback | B17: =B11*B16/B12 -> 65.1
A18: Check | B18: =IF(B15<=B16,"OK: free players reach pity within one comeback","Too slow: free players miss pity this comeback") -> OK: free players reach pity within one comeback
A20: Gem bundles (bought with Robux)
A21: Base gems per Robux (before bonus) | B21: 2
A23: Bundle | B23: Price (Robux) | C23: Bonus gems | D23: Gems | E23: Gems per Robux | F23: Robux per pull | G23: Player pays (USD, approx.) | H23: Gems on first purchase (2x)
A24: Handful | B24: 99 | C24: 0 | D24: =ROUND(B24*$B$21*(1+C24),-1) -> 200 | E24: =D24/B24 -> 2.020202 | F24: =Inputs!$B$8/E24 -> 49.5 | G24: =B24*Inputs!$B$7 -> 1.2375 | H24: =D24*2 -> 400
A25: Pouch | B25: 249 | C25: 0.1 | D25: =ROUND(B25*$B$21*(1+C25),-1) -> 550 | E25: =D25/B25 -> 2.2088353 | F25: =Inputs!$B$8/E25 -> 45.272727 | G25: =B25*Inputs!$B$7 -> 3.1125 | H25: =D25*2 -> 1100
A26: Bag | B26: 499 | C26: 0.15 | D26: =ROUND(B26*$B$21*(1+C26),-1) -> 1150 | E26: =D26/B26 -> 2.3046092 | F26: =Inputs!$B$8/E26 -> 43.391304 | G26: =B26*Inputs!$B$7 -> 6.2375 | H26: =D26*2 -> 2300
A27: Box | B27: 999 | C27: 0.2 | D27: =ROUND(B27*$B$21*(1+C27),-1) -> 2400 | E27: =D27/B27 -> 2.4024024 | F27: =Inputs!$B$8/E27 -> 41.625 | G27: =B27*Inputs!$B$7 -> 12.4875 | H27: =D27*2 -> 4800
A28: Chest | B28: 2499 | C28: 0.25 | D28: =ROUND(B28*$B$21*(1+C28),-1) -> 6250 | E28: =D28/B28 -> 2.5010004 | F28: =Inputs!$B$8/E28 -> 39.984 | G28: =B28*Inputs!$B$7 -> 31.2375 | H28: =D28*2 -> 12500
A29: Vault | B29: 4999 | C29: 0.3 | D29: =ROUND(B29*$B$21*(1+C29),-1) -> 13000 | E29: =D29/B29 -> 2.6005201 | F29: =Inputs!$B$8/E29 -> 38.453846 | G29: =B29*Inputs!$B$7 -> 62.4875 | H29: =D29*2 -> 26000
A31: Bundle used for Robux estimates | B31: Box
A32: Gems per Robux at that bundle | B32: =INDEX($E$24:$E$29,MATCH(B31,$A$24:$A$29,0)) -> 2.4024024
A34: Paying to reach pity sooner (player saves free gems, buys the rest)
A35: Reach pity on day | B35: Free gems saved by then | C35: Gems still needed | D35: Robux to buy them | E35: Player pays (USD, approx.)
A36: 1 | B36: =MIN(A36*$B$11,$B$14*$B$12) -> 310 | C36: =MAX(0,$B$14*$B$12-B36) -> 5690 | D36: =ROUNDUP(C36/$B$32,0) -> 2369 | E36: =D36*Inputs!$B$7 -> 29.6125
A37: 3 | B37: =MIN(A37*$B$11,$B$14*$B$12) -> 930 | C37: =MAX(0,$B$14*$B$12-B37) -> 5070 | D37: =ROUNDUP(C37/$B$32,0) -> 2111 | E37: =D37*Inputs!$B$7 -> 26.3875
A38: 7 | B38: =MIN(A38*$B$11,$B$14*$B$12) -> 2170 | C38: =MAX(0,$B$14*$B$12-B38) -> 3830 | D38: =ROUNDUP(C38/$B$32,0) -> 1595 | E38: =D38*Inputs!$B$7 -> 19.9375
A39: 10 | B39: =MIN(A39*$B$11,$B$14*$B$12) -> 3100 | C39: =MAX(0,$B$14*$B$12-B39) -> 2900 | D39: =ROUNDUP(C39/$B$32,0) -> 1208 | E39: =D39*Inputs!$B$7 -> 15.1
A40: 14 | B40: =MIN(A40*$B$11,$B$14*$B$12) -> 4340 | C40: =MAX(0,$B$14*$B$12-B40) -> 1660 | D40: =ROUNDUP(C40/$B$32,0) -> 691 | E40: =D40*Inputs!$B$7 -> 8.6375
A41: 21 | B41: =MIN(A41*$B$11,$B$14*$B$12) -> 6000 | C41: =MAX(0,$B$14*$B$12-B41) -> 0 | D41: =ROUNDUP(C41/$B$32,0) -> 0 | E41: =D41*Inputs!$B$7 -> 0
A42: This is what you sell: the same reward, sooner. Free players still get there by playing.

Sheet Odds
A1: Pull odds: the game must show exactly these numbers
A2: Roblox rule (May 2026): show each outcome's odds as numbers that add up to 100% before purchase; every outcome must give something; restricted players need a non-random option.
A4: Rarity | B4: Tier | C4: Chance per pull | D4: 1 in... | E4: Chance in one 10-pull | F4: ="Chance in "&Inputs!$B$9&" pulls (ignoring pity)" -> Chance in 60 pulls (ignoring pity) | G4: Luck boost applies? | H4: Chance with a luck boost on
A5: Trainee | B5: Common | C5: 0.6 | D5: =1/C5 -> 1.6666667 | E5: =1-(1-C5)^10 -> 0.99989514 | F5: =1-(1-C5)^Inputs!$B$9 -> 1 | G5: Takes the rest | H5: =1-SUM(H6:H9) -> 0.54
A6: Rookie | B6: Rare | C6: 0.28 | D6: =1/C6 -> 3.5714286 | E6: =1-(1-C6)^10 -> 0.96256094 | F6: =1-(1-C6)^Inputs!$B$9 -> 1 | G6: No | H6: =IF(G6="Yes",C6*$B$11,C6) -> 0.28
A7: Idol | B7: Epic | C7: 0.09 | D7: =1/C7 -> 11.111111 | E7: =1-(1-C7)^10 -> 0.61058388 | F7: =1-(1-C7)^Inputs!$B$9 -> 0.99651275 | G7: Yes | H7: =IF(G7="Yes",C7*$B$11,C7) -> 0.135
A8: Center | B8: Legendary | C8: 0.025 | D8: =1/C8 -> 40 | E8: =1-(1-C8)^10 -> 0.22367038 | F8: =1-(1-C8)^Inputs!$B$9 -> 0.78108428 | G8: Yes | H8: =IF(G8="Yes",C8*$B$11,C8) -> 0.0375
A9: Daesang | B9: Mythic | C9: 0.005 | D9: =1/C9 -> 200 | E9: =1-(1-C9)^10 -> 0.04888987 | F9: =1-(1-C9)^Inputs!$B$9 -> 0.25973904 | G9: Yes | H9: =IF(G9="Yes",C9*$B$11,C9) -> 0.0075
A10: Total | C10: =SUM(C5:C9) -> 1 | D10: =IF(ROUND(C10,6)=1,"OK","Must add up to 100%") -> OK | H10: =SUM(H5:H9) -> 1
A11: Luck boost multiplier (Lucky pass, potion or Concert Boost on) | B11: 1.5
A12: Boost check | B12: =IF(H5>=0,"OK: boosted odds still add up to 100%","Boost too big: Trainee odds fell below zero") -> OK: boosted odds still add up to 100%
A13: While a boost is on, the odds shown in game must switch to the boosted column. Pity must be shown as a number too (e.g. "Center or better by pull 60").
A15: Special version | B15: Chance on any pull | C15: Note
A16: Holo | B16: 0.05 | C16: Rolled separately from rarity. Also made by fusing 5 copies.
A17: Signed | B17: 0.005 | C17: Rolled separately from rarity. Also made by fusing 5 Holos.
A19: Pity
A20: Center or better guaranteed by pull # | B20: =Inputs!$B$9 -> 60
A21: Chance per pull of Center or better | B21: =C8+C9 -> 0.03
A22: Chance pity is needed (no Center+ before it) | B22: =(1-B21)^(B20-1) -> 0.16578007
A23: Average pulls per Center or better (with pity) | B23: =(1-(1-B21)^B20)/B21 -> 27.973111
A25: Most Robux one chase item should cost on average | B25: 10000 | C25: Above this, make it earnable (fusion, events, achievements) rather than pull-only.
A26: Gems per Robux used (Gems tab) | B26: =Gems!$B$32 -> 2.4024024
A28: Chasing | B28: Chance per pull | C28: Average pulls | D28: Average gems | E28: Average Robux | F28: Player pays (USD, approx.) | G28: Verdict
A29: Center or better (with pity) | B29: =B21 -> 0.03 | C29: =B23 -> 27.973111 | D29: =C29*Inputs!$B$8 -> 2797.3111 | E29: =D29/$B$26 -> 1164.3807 | F29: =E29*Inputs!$B$7 -> 14.554759 | G29: =IF(E29<=$B$25,"OK to sell in packs","Too costly: make it earnable") -> OK to sell in packs
A30: Daesang | B30: =C9 -> 0.005 | C30: =1/B30 -> 200 | D30: =C30*Inputs!$B$8 -> 20000 | E30: =D30/$B$26 -> 8325 | F30: =E30*Inputs!$B$7 -> 104.0625 | G30: =IF(E30<=$B$25,"OK to sell in packs","Too costly: make it earnable") -> OK to sell in packs
A31: Holo Center | B31: =C8*B16 -> 0.00125 | C31: =1/B31 -> 800 | D31: =C31*Inputs!$B$8 -> 80000 | E31: =D31/$B$26 -> 33300 | F31: =E31*Inputs!$B$7 -> 416.25 | G31: =IF(E31<=$B$25,"OK to sell in packs","Too costly: make it earnable") -> Too costly: make it earnable
A32: Holo Daesang | B32: =C9*B16 -> 0.00025 | C32: =1/B32 -> 4000 | D32: =C32*Inputs!$B$8 -> 400000 | E32: =D32/$B$26 -> 166500 | F32: =E32*Inputs!$B$7 -> 2081.25 | G32: =IF(E32<=$B$25,"OK to sell in packs","Too costly: make it earnable") -> Too costly: make it earnable
A33: Signed Center | B33: =C8*B17 -> 0.000125 | C33: =1/B33 -> 8000 | D33: =C33*Inputs!$B$8 -> 800000 | E33: =D33/$B$26 -> 333000 | F33: =E33*Inputs!$B$7 -> 4162.5 | G33: =IF(E33<=$B$25,"OK to sell in packs","Too costly: make it earnable") -> Too costly: make it earnable
A34: Signed Daesang | B34: =C9*B17 -> 2.5e-05 | C34: =1/B34 -> 40000 | D34: =C34*Inputs!$B$8 -> 4000000 | E34: =D34/$B$26 -> 1665000 | F34: =E34*Inputs!$B$7 -> 20812.5 | G34: =IF(E34<=$B$25,"OK to sell in packs","Too costly: make it earnable") -> Too costly: make it earnable

Sheet Revenue
A1: Revenue per player (first 30 days)
A2: Every rate here is a placeholder guess, not a benchmark. Replace the yellow cells with Creator Analytics numbers after launch.
A4: Players
A5: New players in the cohort | B5: 1000
A6: Still playing on day 1 | B6: 0.25
A7: Still playing on day 7 | B7: 0.08
A8: Still playing on day 30 | B8: 0.03
A9: Check | B9: =IF(AND(B6>=B7,B7>=B8,B8>0),"OK","Day 1 must be >= day 7 >= day 30 > 0") -> OK
A11: Stage | B11: Share of new players
A12: New | B12: 1
A13: Day 1 | B13: =B6 -> 0.25
A14: Day 7 | B14: =B7 -> 0.08
A15: Day 30 | B15: =B8 -> 0.03
A17: Product | B17: Type | C17: Pack-related? (restricted in some regions) | D17: Price (Robux) | E17: Offered to | F17: Players at that stage | G17: Chance one of them buys | H17: Chance after regional limits | I17: Buys per buyer (30 days) | J17: Chance a new player buys | K17: Buyers | L17: Robux players spend | M17: Robux you receive | N17: Your cash after DevEx (USD) | O17: Share of your revenue
A18: Debut Pack (fixed contents, no randomness) | B18: One-time offer | C18: No | D18: 99 | E18: New | F18: =$B$5*INDEX($B$12:$B$15,MATCH(E18,$A$12:$A$15,0)) -> 1000 | G18: 0.015 | H18: =G18*IF(C18="Yes",1-Inputs!$B$12*(1-Inputs!$B$13),1) -> 0.015 | I18: 1 | J18: =F18/$B$5*H18 -> 0.015 | K18: =F18*H18 -> 15 | L18: =K18*I18*D18 -> 1485 | M18: =L18*Inputs!$B$6 -> 1039.5 | N18: =M18*Inputs!$B$5 -> 3.9501 | O18: =IF($B$47=0,0,N18/$B$47) -> 0.050556688
A19: Auto-Stream | B19: Gamepass | C19: No | D19: 199 | E19: Day 1 | F19: =$B$5*INDEX($B$12:$B$15,MATCH(E19,$A$12:$A$15,0)) -> 250 | G19: 0.04 | H19: =G19*IF(C19="Yes",1-Inputs!$B$12*(1-Inputs!$B$13),1) -> 0.04 | I19: 1 | J19: =F19/$B$5*H19 -> 0.01 | K19: =F19*H19 -> 10 | L19: =K19*I19*D19 -> 1990 | M19: =L19*Inputs!$B$6 -> 1393 | N19: =M19*Inputs!$B$5 -> 5.2934 | O19: =IF($B$47=0,0,N19/$B$47) -> 0.067749366
A20: 2x Hype | B20: Gamepass | C20: No | D20: 149 | E20: Day 1 | F20: =$B$5*INDEX($B$12:$B$15,MATCH(E20,$A$12:$A$15,0)) -> 250 | G20: 0.03 | H20: =G20*IF(C20="Yes",1-Inputs!$B$12*(1-Inputs!$B$13),1) -> 0.03 | I20: 1 | J20: =F20/$B$5*H20 -> 0.0075 | K20: =F20*H20 -> 7.5 | L20: =K20*I20*D20 -> 1117.5 | M20: =L20*Inputs!$B$6 -> 782.25 | N20: =M20*Inputs!$B$5 -> 2.97255 | O20: =IF($B$47=0,0,N20/$B$47) -> 0.038045184
A21: 3x Open | B21: Gamepass | C21: Yes | D21: 249 | E21: Day 1 | F21: =$B$5*INDEX($B$12:$B$15,MATCH(E21,$A$12:$A$15,0)) -> 250 | G21: 0.02 | H21: =G21*IF(C21="Yes",1-Inputs!$B$12*(1-Inputs!$B$13),1) -> 0.0179 | I21: 1 | J21: =F21/$B$5*H21 -> 0.004475 | K21: =F21*H21 -> 4.475 | L21: =K21*I21*D21 -> 1114.275 | M21: =L21*Inputs!$B$6 -> 779.9925 | N21: =M21*Inputs!$B$5 -> 2.9639715 | O21: =IF($B$47=0,0,N21/$B$47) -> 0.037935389
A22: Offline earnings 24h | B22: Gamepass | C22: No | D22: 149 | E22: Day 1 | F22: =$B$5*INDEX($B$12:$B$15,MATCH(E22,$A$12:$A$15,0)) -> 250 | G22: 0.015 | H22: =G22*IF(C22="Yes",1-Inputs!$B$12*(1-Inputs!$B$13),1) -> 0.015 | I22: 1 | J22: =F22/$B$5*H22 -> 0.00375 | K22: =F22*H22 -> 3.75 | L22: =K22*I22*D22 -> 558.75 | M22: =L22*Inputs!$B$6 -> 391.125 | N22: =M22*Inputs!$B$5 -> 1.486275 | O22: =IF($B$47=0,0,N22/$B$47) -> 0.019022592
A23: Gem bundle (average) | B23: Developer product | C23: Yes | D23: 499 | E23: Day 1 | F23: =$B$5*INDEX($B$12:$B$15,MATCH(E23,$A$12:$A$15,0)) -> 250 | G23: 0.03 | H23: =G23*IF(C23="Yes",1-Inputs!$B$12*(1-Inputs!$B$13),1) -> 0.02685 | I23: 2.5 | J23: =F23/$B$5*H23 -> 0.0067125 | K23: =F23*H23 -> 6.7125 | L23: =K23*I23*D23 -> 8373.8438 | M23: =L23*Inputs!$B$6 -> 5861.6906 | N23: =M23*Inputs!$B$5 -> 22.274424 | O23: =IF($B$47=0,0,N23/$B$47) -> 0.28508674
A24: Luck potion | B24: Developer product | C24: Yes | D24: 49 | E24: Day 1 | F24: =$B$5*INDEX($B$12:$B$15,MATCH(E24,$A$12:$A$15,0)) -> 250 | G24: 0.02 | H24: =G24*IF(C24="Yes",1-Inputs!$B$12*(1-Inputs!$B$13),1) -> 0.0179 | I24: 4 | J24: =F24/$B$5*H24 -> 0.004475 | K24: =F24*H24 -> 4.475 | L24: =K24*I24*D24 -> 877.1 | M24: =L24*Inputs!$B$6 -> 613.97 | N24: =M24*Inputs!$B$5 -> 2.333086 | O24: =IF($B$47=0,0,N24/$B$47) -> 0.029860788
A25: Card shop: pick the exact card (no randomness) | B25: Developer product | C25: No | D25: 299 | E25: Day 1 | F25: =$B$5*INDEX($B$12:$B$15,MATCH(E25,$A$12:$A$15,0)) -> 250 | G25: 0.02 | H25: =G25*IF(C25="Yes",1-Inputs!$B$12*(1-Inputs!$B$13),1) -> 0.02 | I25: 1.5 | J25: =F25/$B$5*H25 -> 0.005 | K25: =F25*H25 -> 5 | L25: =K25*I25*D25 -> 2242.5 | M25: =L25*Inputs!$B$6 -> 1569.75 | N25: =M25*Inputs!$B$5 -> 5.96505 | O25: =IF($B$47=0,0,N25/$B$47) -> 0.076345705
A26: 8x Open | B26: Gamepass | C26: Yes | D26: 799 | E26: Day 7 | F26: =$B$5*INDEX($B$12:$B$15,MATCH(E26,$A$12:$A$15,0)) -> 80 | G26: 0.03 | H26: =G26*IF(C26="Yes",1-Inputs!$B$12*(1-Inputs!$B$13),1) -> 0.02685 | I26: 1 | J26: =F26/$B$5*H26 -> 0.002148 | K26: =F26*H26 -> 2.148 | L26: =K26*I26*D26 -> 1716.252 | M26: =L26*Inputs!$B$6 -> 1201.3764 | N26: =M26*Inputs!$B$5 -> 4.5652303 | O26: =IF($B$47=0,0,N26/$B$47) -> 0.058429641
A27: Lucky | B27: Gamepass | C27: Yes | D27: 349 | E27: Day 7 | F27: =$B$5*INDEX($B$12:$B$15,MATCH(E27,$A$12:$A$15,0)) -> 80 | G27: 0.04 | H27: =G27*IF(C27="Yes",1-Inputs!$B$12*(1-Inputs!$B$13),1) -> 0.0358 | I27: 1 | J27: =F27/$B$5*H27 -> 0.002864 | K27: =F27*H27 -> 2.864 | L27: =K27*I27*D27 -> 999.536 | M27: =L27*Inputs!$B$6 -> 699.6752 | N27: =M27*Inputs!$B$5 -> 2.6587658 | O27: =IF($B$47=0,0,N27/$B$47) -> 0.034029111
A28: +1 Squad Slot | B28: Gamepass | C28: No | D28: 299 | E28: Day 7 | F28: =$B$5*INDEX($B$12:$B$15,MATCH(E28,$A$12:$A$15,0)) -> 80 | G28: 0.04 | H28: =G28*IF(C28="Yes",1-Inputs!$B$12*(1-Inputs!$B$13),1) -> 0.04 | I28: 1 | J28: =F28/$B$5*H28 -> 0.0032 | K28: =F28*H28 -> 3.2 | L28: =K28*I28*D28 -> 956.8 | M28: =L28*Inputs!$B$6 -> 669.76 | N28: =M28*Inputs!$B$5 -> 2.545088 | O28: =IF($B$47=0,0,N28/$B$47) -> 0.032574167
A29: VIP | B29: Gamepass | C29: No | D29: 499 | E29: Day 7 | F29: =$B$5*INDEX($B$12:$B$15,MATCH(E29,$A$12:$A$15,0)) -> 80 | G29: 0.02 | H29: =G29*IF(C29="Yes",1-Inputs!$B$12*(1-Inputs!$B$13),1) -> 0.02 | I29: 1 | J29: =F29/$B$5*H29 -> 0.0016 | K29: =F29*H29 -> 1.6 | L29: =K29*I29*D29 -> 798.4 | M29: =L29*Inputs!$B$6 -> 558.88 | N29: =M29*Inputs!$B$5 -> 2.123744 | O29: =IF($B$47=0,0,N29/$B$47) -> 0.027181454
... A34: Cosmetics (outfits, skins, emotes) | B34: Developer product | C34: No | D34: 149 | E34: Day 7 | F34: =$B$5*INDEX($B$12:$B$15,MATCH(E34,$A$12:$A$15,0)) -> 80 | G34: 0.05 | H34: =G34*IF(C34="Yes",1-Inputs!$B$12*(1-Inputs!$B$13),1) -> 0.05 | I34: 2 | J34: =F34/$B$5*H34 -> 0.004 | K34: =F34*H34 -> 4 | L34: =K34*I34*D34 -> 1192 | M34: =L34*Inputs!$B$6 -> 834.4 | N34: =M34*Inputs!$B$5 -> 3.17072 | O34: =IF($B$47=0,0,N34/$B$47) -> 0.04058153
A35: Total (Robux products) | L35: =SUM(L18:L34) -> 27872.217 | M35: =SUM(M18:M34) -> 19510.552 | N35: =SUM(N18:N34) -> 74.140097 | O35: =SUM(O18:O34) -> 0.94890704
A37: Fan Club subscription (priced in real money)
A38: Price per month (USD) | B38: 4.99
A39: Offered to | B39: Day 7
A40: Chance one of them subscribes | B40: 0.02
A41: Months paid in the first 30 days | B41: 1
A42: Your share after app store and Roblox fees | B42: 0.5 | C42: Placeholder. Roblox's Earn on Roblox page gives no subscription share; check Creator Hub.
A43: Subscribers in the cohort | B43: =$B$5*INDEX($B$12:$B$15,MATCH(B39,$A$12:$A$15,0))*B40 -> 1.6
A44: Your cash from subscriptions (USD) | B44: =B43*B41*B38*B42 -> 3.992
A46: Results
A47: Your total revenue from this cohort (USD) | B47: =N35+B44 -> 78.132097
A48: Revenue per new player, first 30 days (USD) | B48: =B47/B5 -> 0.078132097
A49: Revenue per player still playing on day 7 (USD) | B49: =IF(B7=0,0,B47/(B5*B7)) -> 0.97665121
...

Sheet Growth
A1: Growth: where players come from, who stays, what they are worth
A2: Weekly model of the first 26 weeks. Yellow cells are placeholders: replace them with Creator Analytics numbers.
A4: Where new players come from
A5: Organic new players in week 1 (Roblox recommendations and search) | B5: 1500
A6: Organic growth per week | B6: 0.03 | C6: Roblox recommendations reward 28-day retention, play days, co-play and spend days (DevForum, June 2026).
A7: New players from friend invites per week, per 100 average daily players | B7: 5 | C7: Friend bonuses (luck per friend, gifting, co-op events) push this up.
A8: New players per week from off-Roblox content (TikTok, YouTube links) | B8: 300 | C8: Direct links to your game page also earn Audience Expansion Rewards (below).
A9: Paid ads budget per week (USD) | B9: 0
A10: Cost per new player from ads (USD) | B10: 0.3 | C10: Placeholder. Check your cost in Roblox Ads Manager.
A11: A comeback starts every (weeks) | B11: =MAX(1,ROUND(Inputs!$B$10/7,0)) -> 3 | C11: From the comeback length on Inputs.
A12: New players in a comeback week (x normal) | B12: 1.5
A13: Lapsed players who come back in a comeback week | B13: 0.05
A14: Days a returning player plays during that week | B14: 3
A16: Retention (from the Revenue tab)
A17: Still playing on day 1 | B17: =Revenue!$B$6 -> 0.25
A18: Still playing on day 7 | B18: =Revenue!$B$7 -> 0.08
A19: Still playing on day 30 | B19: =Revenue!$B$8 -> 0.03
A20: Curve steepness, days 1-7 (fitted) | B20: =LN(B18/B17)/LN(7) -> -0.58555339
A21: Curve steepness after day 7 (fitted) | B21: =LN(B19/B18)/LN(30/7) -> -0.6739764 | C21: Retention follows a power curve through day 1, day 7 and day 30, then keeps the same slope after day 30.
A22: Player-days in a new player's first 30 days | B22: =7*SUM(B44:B47)+2*B48 -> 2.8950392
A24: Money
A25: 30-day revenue per new player (Revenue tab) | B25: =Revenue!$B$48 -> 0.078132097
A26: Revenue per daily player per day (fitted) | B26: =B25/B22 -> 0.026988269 | C26: Spread so the first 30 days match the Revenue tab.
A27: Spending after the first month (x first-month rate) | B27: 1 | C27: Players who stay often spend more; raise this once you see real data.
A28: Share of your players who are Roblox 'Active Spenders' | B28: 0.1 | C28: Spent $9.99+ on Roblox in the last 60 days (Creator Rewards definition).
A29: Share of their play days that qualify | B29: 0.6 | C29: 10+ minutes in your game that day, and yours is among the first 3 games they launch.
A30: Robux per qualifying Active Spender day | B30: 5 | C30: Creator Rewards, Daily Engagement Rewards (DevForum, July 2025). May change.
A31: Off-Roblox new players who are new to Roblox, or back after 60+ days | B31: 0.1 | C31: Counts only if they arrive by a direct link or search your game by name, then play 10+ minutes.
A32: Their Robux purchases in their first two months (USD, counted up to $100) | B32: 3 | C32: Average including the many who buy nothing.
A33: Audience Expansion revenue share | B33: 0.35 | C33: Creator Rewards, Audience Expansion Rewards. Paid after a 60-day hold.
A34: Creator Rewards per daily player per day (USD) | B34: =B28*B29*B30*Inputs!$B$5 -> 0.00114
A36: Results
A37: Average daily players in week 26 | B37: =I98 -> 2547.3155
A38: Revenue over 26 weeks (USD, purchases + Creator Rewards) | B38: =J99+K99 -> 10394.528
A39: Value of one new player over 26 weeks (USD) | B39: =B26*7*(SUM(B44:B48)+B27*SUM(B49:B69))+B34*7*SUM(B44:B69) -> 0.14390095
A40: Do ads pay back within 26 weeks? | B40: =IF(B10<=0,"-",IF(B39>=B10,"OK: an ad player earns back their cost","No: an ad player costs more than they earn")) -> No: an ad player costs more than they earn
A41: Revenue from Creator Rewards (share of total) | B41: =IF(B38=0,0,K99/B38) -> 0.12775725
A43: Weeks since install | B43: Share playing on a typical day that week
A44: 0 | B44: =(1+$B$17*(1^$B$20+2^$B$20+3^$B$20+4^$B$20+5^$B$20+6^$B$20))/7 -> 0.26342665 | C44: Install week: day 0 plus days 1-6 averaged.
A45: 1 | B45: =$B$18*((7*A45+3)/7)^$B$21 -> 0.06290566
...

Sheet Heat maps
A1: Heat maps: when money comes in, and where play time goes
A2: Top: planned timing of each purchase (blue) turned into revenue by player age (heat). Bottom: planned share of play time by feature. Replace with tracked data after launch.
A4: When purchases happen (each row adds up to 100%)
A5: Product | B5: Your cash, first 30 days (USD) | C5: Day 0 (first session) | D5: Days 1-2 | E5: Days 3-6 | F5: Week 2 | G5: Weeks 3-4 | H5: Check
A6: Debut Pack (fixed contents, no randomness) | B6: =Revenue!N18 -> 3.9501 | C6: 0.7 | D6: 0.25 | E6: 0.05 | F6: 0 | G6: 0 | H6: =IF(ROUND(SUM(C6:G6),6)=1,"OK","Must add up to 100%") -> OK
A7: Auto-Stream | B7: =Revenue!N19 -> 5.2934 | C7: 0 | D7: 0.45 | E7: 0.3 | F7: 0.15 | G7: 0.1 | H7: =IF(ROUND(SUM(C7:G7),6)=1,"OK","Must add up to 100%") -> OK
A8: 2x Hype | B8: =Revenue!N20 -> 2.97255 | C8: 0 | D8: 0.4 | E8: 0.3 | F8: 0.18 | G8: 0.12 | H8: =IF(ROUND(SUM(C8:G8),6)=1,"OK","Must add up to 100%") -> OK
A9: 3x Open | B9: =Revenue!N21 -> 2.9639715 | C9: 0 | D9: 0.4 | E9: 0.3 | F9: 0.18 | G9: 0.12 | H9: =IF(ROUND(SUM(C9:G9),6)=1,"OK","Must add up to 100%") -> OK
A10: Offline earnings 24h | B10: =Revenue!N22 -> 1.486275 | C10: 0 | D10: 0.3 | E10: 0.35 | F10: 0.2 | G10: 0.15 | H10: =IF(ROUND(SUM(C10:G10),6)=1,"OK","Must add up to 100%") -> OK
A11: Gem bundle (average) | B11: =Revenue!N23 -> 22.274424 | C11: 0 | D11: 0.2 | E11: 0.25 | F11: 0.27 | G11: 0.28 | H11: =IF(ROUND(SUM(C11:G11),6)=1,"OK","Must add up to 100%") -> OK
A12: Luck potion | B12: =Revenue!N24 -> 2.333086 | C12: 0 | D12: 0.25 | E12: 0.25 | F12: 0.22 | G12: 0.28 | H12: =IF(ROUND(SUM(C12:G12),6)=1,"OK","Must add up to 100%") -> OK
A13: Card shop: pick the exact card (no randomness) | B13: =Revenue!N25 -> 5.96505 | C13: 0 | D13: 0.15 | E13: 0.25 | F13: 0.3 | G13: 0.3 | H13: =IF(ROUND(SUM(C13:G13),6)=1,"OK","Must add up to 100%") -> OK
A14: 8x Open | B14: =Revenue!N26 -> 4.5652303 | C14: 0 | D14: 0 | E14: 0 | F14: 0.55 | G14: 0.45 | H14: =IF(ROUND(SUM(C14:G14),6)=1,"OK","Must add up to 100%") -> OK
A15: Lucky | B15: =Revenue!N27 -> 2.6587658 | C15: 0 | D15: 0 | E15: 0 | F15: 0.5 | G15: 0.5 | H15: =IF(ROUND(SUM(C15:G15),6)=1,"OK","Must add up to 100%") -> OK
A16: +1 Squad Slot | B16: =Revenue!N28 -> 2.545088 | C16: 0 | D16: 0 | E16: 0 | F16: 0.5 | G16: 0.5 | H16: =IF(ROUND(SUM(C16:G16),6)=1,"OK","Must add up to 100%") -> OK
A17: VIP | B17: =Revenue!N29 -> 2.123744 | C17: 0 | D17: 0 | E17: 0 | F17: 0.45 | G17: 0.55 | H17: =IF(ROUND(SUM(C17:G17),6)=1,"OK","Must add up to 100%") -> OK
... A22: Cosmetics (outfits, skins, emotes) | B22: =Revenue!N34 -> 3.17072 | C22: 0 | D22: 0 | E22: 0 | F22: 0.45 | G22: 0.55 | H22: =IF(ROUND(SUM(C22:G22),6)=1,"OK","Must add up to 100%") -> OK
A23: Fan Club subscription | B23: =Revenue!B44 -> 3.992 | C23: 0 | D23: 0 | E23: 0 | F23: 0.6 | G23: 0.4 | H23: =IF(ROUND(SUM(C23:G23),6)=1,"OK","Must add up to 100%") -> OK
A25: Revenue heat map: your cash by product and player age (USD)
A26: Product | B26: Total | C26: Day 0 (first session) | D26: Days 1-2 | E26: Days 3-6 | F26: Week 2 | G26: Weeks 3-4
A27: Debut Pack (fixed contents, no randomness) | B27: =SUM(C27:G27) -> 3.9501 | C27: =$B6*C6 -> 2.76507 | D27: =$B6*D6 -> 0.987525 | E27: =$B6*E6 -> 0.197505 | F27: =$B6*F6 -> 0 | G27: =$B6*G6 -> 0
A28: Auto-Stream | B28: =SUM(C28:G28) -> 5.2934 | C28: =$B7*C7 -> 0 | D28: =$B7*D7 -> 2.38203 | E28: =$B7*E7 -> 1.58802 | F28: =$B7*F7 -> 0.79401 | G28: =$B7*G7 -> 0.52934
A29: 2x Hype | B29: =SUM(C29:G29) -> 2.97255 | C29: =$B8*C8 -> 0 | D29: =$B8*D8 -> 1.18902 | E29: =$B8*E8 -> 0.891765 | F29: =$B8*F8 -> 0.535059 | G29: =$B8*G8 -> 0.356706
A30: 3x Open | B30: =SUM(C30:G30) -> 2.9639715 | C30: =$B9*C9 -> 0 | D30: =$B9*D9 -> 1.1855886 | E30: =$B9*E9 -> 0.88919145 | F30: =$B9*F9 -> 0.53351487 | G30: =$B9*G9 -> 0.35567658
A31: Offline earnings 24h | B31: =SUM(C31:G31) -> 1.486275 | C31: =$B10*C10 -> 0 | D31: =$B10*D10 -> 0.4458825 | E31: =$B10*E10 -> 0.52019625 | F31: =$B10*F10 -> 0.297255 | G31: =$B10*G10 -> 0.22294125
A32: Gem bundle (average) | B32: =SUM(C32:G32) -> 22.274424 | C32: =$B11*C11 -> 0 | D32: =$B11*D11 -> 4.4548849 | E32: =$B11*E11 -> 5.5686061 | F32: =$B11*F11 -> 6.0140946 | G32: =$B11*G11 -> 6.2368388
A33: Luck potion | B33: =SUM(C33:G33) -> 2.333086 | C33: =$B12*C12 -> 0 | D33: =$B12*D12 -> 0.5832715 | E33: =$B12*E12 -> 0.5832715 | F33: =$B12*F12 -> 0.51327892 | G33: =$B12*G12 -> 0.65326408
A34: Card shop: pick the exact card (no randomness) | B34: =SUM(C34:G34) -> 5.96505 | C34: =$B13*C13 -> 0 | D34: =$B13*D13 -> 0.8947575 | E34: =$B13*E13 -> 1.4912625 | F34: =$B13*F13 -> 1.789515 | G34: =$B13*G13 -> 1.789515
A35: 8x Open | B35: =SUM(C35:G35) -> 4.5652303 | C35: =$B14*C14 -> 0 | D35: =$B14*D14 -> 0 | E35: =$B14*E14 -> 0 | F35: =$B14*F14 -> 2.5108767 | G35: =$B14*G14 -> 2.0543536
A36: Lucky | B36: =SUM(C36:G36) -> 2.6587658 | C36: =$B15*C15 -> 0 | D36: =$B15*D15 -> 0 | E36: =$B15*E15 -> 0 | F36: =$B15*F15 -> 1.3293829 | G36: =$B15*G15 -> 1.3293829
A37: +1 Squad Slot | B37: =SUM(C37:G37) -> 2.545088 | C37: =$B16*C16 -> 0 | D37: =$B16*D16 -> 0 | E37: =$B16*E16 -> 0 | F37: =$B16*F16 -> 1.272544 | G37: =$B16*G16 -> 1.272544
A38: VIP | B38: =SUM(C38:G38) -> 2.123744 | C38: =$B17*C17 -> 0 | D38: =$B17*D17 -> 0 | E38: =$B17*E17 -> 0 | F38: =$B17*F17 -> 0.9556848 | G38: =$B17*G17 -> 1.1680592
... A44: Fan Club subscription | B44: =SUM(C44:G44) -> 3.992 | C44: =$B23*C23 -> 0 | D44: =$B23*D23 -> 0 | E44: =$B23*E23 -> 0 | F44: =$B23*F23 -> 2.3952 | G44: =$B23*G23 -> 1.5968
A45: Total | B45: =SUM(B27:B44) -> 78.132097 | C45: =SUM(C27:C44) -> 2.76507 | D45: =SUM(D27:D44) -> 12.12296 | E45: =SUM(E27:E44) -> 11.729818 | F45: =SUM(F27:F44) -> 25.528768 | G45: =SUM(G27:G44) -> 25.985481
A46: Share of 30-day revenue | C46: =IF($B$45=0,0,C45/$B$45) -> 0.035389681 | D46: =IF($B$45=0,0,D45/$B$45) -> 0.15515979 | E46: =IF($B$45=0,0,E45/$B$45) -> 0.15012803 | F46: =IF($B$45=0,0,F45/$B$45) -> 0.32673855 | G46: =IF($B$45=0,0,G45/$B$45) -> 0.33258395
A47: If most money arrives in weeks 2-4, retention matters more than better first-session offers.
A49: Where play time goes as players age (planned share of play time, each column adds up to 100%)
A50: Feature | B50: Minutes 0-5 | C50: Rest of first session | D50: Days 2-3 | E50: Days 4-7 | F50: Weeks 2-4 | G50: Month 2+
A51: Streaming (clicking) and Fever | B51: 0.55 | C51: 0.3 | D51: 0.18 | E51: 0.12 | F51: 0.08 | G51: 0.06
A52: Pack opening | B52: 0.25 | C52: 0.2 | D52: 0.15 | E52: 0.12 | F52: 0.1 | G52: 0.08
...

Sheet Tracking
A1: Tracking plan: log these so the model and heat maps fill with real data
A2: All methods are on AnalyticsService (Roblox Creator Docs). Store each player's first-join date and send "days since first join" with every event.
A4: Event | B4: When to log it | C4: AnalyticsService method | D4: What to include | E4: What it tells you (tab)
A5: Onboarding steps | B5: Each first: joined, first click, first Fever, first pack, named group, first boss win, reached Busking Street, hit first wall | C5: LogOnboardingFunnelStepEvent | D5: step number and name | E5: Where new players quit; first-play bounce (Pacing)
A6: Zone reached | B6: Entering each zone | C6: LogProgressionCompleteEvent | D6: path "Zones", level = zone number, zone name | E6: Real arrival times vs. the model (Pacing)
A7: Boss attempts | B7: Start, fail and win of each boss | C7: LogProgressionStartEvent / FailEvent / CompleteEvent | D7: boss level and name | E7: Which walls stop players (Pacing)
A8: Gems earned and spent | B8: Every gem change | C8: LogEconomyEvent | D8: Source or Sink, "Gems", amount, ending balance, transaction type (Quest, Drop, Pack, Shop), item SKU | E8: Real free gems per day; days to pity (Gems)
A9: Hype earned and spent | B9: Batched once a minute, not per click | C9: LogEconomyEvent | D9: Source or Sink, "Hype", amount, ending balance | E9: Real Hype per second (Pacing)
A10: Pack opened | B10: Every pull | C10: LogCustomEvent "PackOpened" | D10: rarity, version (Holo/Signed), pity count, boost on or off | E10: Real drop rates match the posted odds (Odds)
A11: Purchase | B11: After each successful Robux purchase | C11: LogCustomEvent "Purchase" | D11: value = Robux price; product, days since first join, zone | E11: Real revenue heat map by product and player age (Heat maps)
A12: Shop visit | B12: Open shop, view item, purchase prompt, bought | C12: LogFunnelStepEvent "Shop" | D12: one funnel session ID per visit, step | E12: Which offers convert and where buyers drop (Revenue)
A13: Feature time | B13: When a player leaves a feature (batched) | C13: LogCustomEvent "FeatureTime" | D13: value = seconds; feature name, days since first join | E13: Real play-time heat map (Heat maps)
A14: Playing with friends | B14: While a friend is in the same server | C14: LogCustomEvent "PlayWithFriend" | D14: value = minutes together | E14: Co-play, a discovery signal (Growth)
A15: Comeback return | B15: First join during a comeback | C15: LogCustomEvent "ComebackJoin" | D15: days since last visit | E15: How many lapsed players a comeback wins back (Growth)
A16: Session recap | B16: When the end-of-session recap shows | C16: LogCustomEvent "SessionRecap" | D16: value = session minutes | E16: Whether sessions end on a high, and next-day return
